Workbook
Name Slicer_Brand: #N/A
Name Slicer_Category: #N/A
Name Slicer_Clean_Payment_Mode: #N/A
Name Slicer_Membership: #N/A
Name Slicer_Month: #N/A
Name Slicer_Region: #N/A
Name Slicer_Sales_Channel: #N/A

Sheet slicer
A3: Row Labels | B3: Sum of Sales Amount
A4: Accessories | B4: 166486.52
A5: Belts | B5: 179789.99
A6: Footwear | B6: 521388.97
A7: Handbags | B7: 994021.98
A8: Jewellery | B8: 850930.2
A9: Kids Wear | B9: 184043.76
A10: Men Ethnic | B10: 508021.06
A11: Men Jeans | B11: 277306.93
A12: Men Shirts | B12: 184667.23
A13: Men Trousers | B13: 206033.29
A14: Men T-Shirts | B14: 312534.72
A15: Sportswear | B15: 259644.52
... A24: Grand Total | B24: 9227180

Sheet Dashboard

Sheet kpi
A1: kpi | B1: values
A2: Total Sales | B2: =SUM(Sales_Transactions!M:M) -> 9227180
A3: Total Profit | B3: =SUM(Sales_Transactions!O:O) -> 1804518.5
A4: Total Quantity | B4: =SUM(Sales_Transactions!G:G) -> 6118
A5: Profit Margin % | B5: =SUM(Sales_Transactions!O:O)/SUM(Sales_Transactions!M:M) -> 0.19556555
A6: Total Customers | B6: =COUNTA(_xlfn.UNIQUE(Sales_Transactions!B2:B2924)) -> 364
A7: Total Cost | B7: =SUM(tblSales[Cost Amount]) -> 6596441.1
A8: Total Transactions | B8: =COUNTA(_xlfn.UNIQUE(tblSales[Invoice No])) -> 2995

Sheet monthly
A3: Row Labels | B3: Sum of Sales Amount | C3: Sum of Profit
A4: 2024 | B4: 7613439.2 | C4: 1489359.7
A5: Apr | B5: 683356.93 | C5: 132559.46
A6: May | B6: 715370.42 | C6: 143214.56
A7: Jun | B7: 706442.99 | C7: 126683.88
A8: Jul | B8: 575940.09 | C8: 110065.95
A9: Aug | B9: 624765.64 | C9: 122773.23
A10: Sep | B10: 842808.66 | C10: 177387.37
A11: Oct | B11: 1519147.1 | C11: 301165.34
A12: Nov | B12: 1054251.4 | C12: 194655.84
A13: Dec | B13: 891356.08 | C13: 180854.07
A14: 2025 | B14: 1613740.7 | C14: 315158.84
A15: Jan | B15: 305174.24 | C15: 54860.77
... A18: Grand Total | B18: 9227180 | C18: 1804518.5

Sheet sales
A3: Row Labels | B3: Sum of Sales Amount | C3: Sum of Profit
A4: Accessories | B4: 166486.52 | C4: 56077.74
A5: Belts | B5: 179789.99 | C5: 37446.83
A6: Footwear | B6: 521388.97 | C6: 89384.64
A7: Handbags | B7: 994021.98 | C7: 213991.74
A8: Jewellery | B8: 850930.2 | C8: 150422.21
A9: Kids Wear | B9: 184043.76 | C9: 33376.6
A10: Men Ethnic | B10: 508021.06 | C10: 96328.01
A11: Men Jeans | B11: 277306.93 | C11: 41174.84
A12: Men Shirts | B12: 184667.23 | C12: 35427.94
A13: Men Trousers | B13: 206033.29 | C13: 42136.12
A14: Men T-Shirts | B14: 312534.72 | C14: 94494.79
A15: Sportswear | B15: 259644.52 | C15: 49595.82
... A24: Grand Total | B24: 9227180 | C24: 1804518.5
A44: Row Labels | B44: Sum of Sales Amount
A45: Cash | B45: 3843.11
A46: Credit Card | B46: 3025.98
A47: Debit Card | B47: 3864
A48: UPI | B48: 2027.41
A49: Cash | B49: 1759609.4
A50: Credit Card | B50: 2017983.7
A51: Debit Card | B51: 1875839.6
A52: EMI | B52: 343465.97
A53: Net Banking | B53: 600470.11
A54: UPI | B54: 2617050.7
A55: Grand Total | B55: 9227180

Sheet product sales
A3: Row Labels | B3: Sum of Sales Amount | C3: Sum of Profit
A4: GRT Jewellers Sling Bag Olive | B4: 483225.47 | C4: 114878.08
A5: Aurelia Earrings Sky Blue | B5: 243671.75 | C5: 31775.83
A6: Global Desi Earrings Green | B6: 207013.85 | C6: 40366.38
A7: Max Fashion Printed Saree Brown | B7: 197082.8 | C7: 44505.57
A8: Nike Earrings Teal | B8: 173911.74 | C8: 32108.45
A9: Westside Straight Fit Charcoal | B9: 147220.91 | C9: 35120.92
A10: Max Fashion Georgette Saree Brown | B10: 138420.26 | C10: 26849.36
A11: Global Desi Analog Watch Cream | B11: 133863.46 | C11: 24220.3
A12: Wrangler Ring White | B12: 121803.88 | C12: 32689.22
A13: Aurelia Analog Watch Purple | B13: 111670.81 | C13: 18835.72
A14: Grand Total | B14: 1957884.9 | C14: 401349.83

Sheet region
A3: Row Labels | B3: Sum of Sales Amount | C3: Sum of Profit
A4: South Zone 1 | B4: 4463451.9 | C4: 866892.49
A5: South Zone 2 | B5: 2554815.9 | C5: 493806.97
A6: South Zone 3 | B6: 2208912.1 | C6: 443819.08
A7: Grand Total | B7: 9227180 | C7: 1804518.5
A25: Row Labels | B25: Sum of Sales Amount
A26: Cash | B26: 1763452.5
A27: Credit Card | B27: 2021009.7
A28: Debit Card | B28: 1879703.6
A29: EMI | B29: 343465.97
A30: Net Banking | B30: 600470.11
A31: UPI | B31: 2619078.1
A32: Grand Total | B32: 9227180

Sheet channel
A3: Row Labels | B3: Sum of Sales Amount
A4: Offline | B4: 6048775.9
A5: Online | B5: 3178404
A6: Grand Total | B6: 9227180

Sheet discount return analysis
A3: Row Labels | B3: Average of Discount % | C3: Average of Profit Margin
A4: 0-5% | B4: 1.5014164 | C4: 0.27543022
A5: 10-15% | B5: 15 | C5: 0.17266696
A6: 15-20% | B6: 20 | C6: 0.12893568
A7: 20%+ | B7: 27.503618 | C7: 0.050592098
A8: 5-10% | B8: 10 | C8: 0.2190196
A9: Grand Total | B9: 12.57 | C9: 0.1861443

Sheet Return status
A3: Row Labels | B3: Count of Invoice No
A4: Not Returned | B4: 2855
A5: Returned | B5: 145
A6: Grand Total | B6: 3000

Sheet Sales_Transactions
A1: Invoice No | B1: Invoice Date | C1: Customer_ID | D1: Product_ID | E1: Store_ID | F1: Employee_ID | G1: Quantity | H1: Unit Price | I1: Discount % | J1: Discount Amount | K1: GST % | L1: GST Amount | M1: Sales Amount | N1: Cost Amount | O1: Profit | P1: Payment Mode | Q1: Clean Payment Mode | R1: Sales Channel | S1: Return Status | T1: Order Time | U1: Day Type | V1: Month | W1: Month No | X1: Year | Y1: Month Year | Z1: Category | AA1: Subcategory | AB1: Brand | AC1: Store Name | AD1: Region | AE1: Customer Name | AF1: Membership | AG1: Employee Name | AH1: Month Sort | AI1: Month Start | AJ1: Product Name | AK1: Profit Margin | AL1: Discount Band
A2: INV100001 | B2: 45642 | C2: CUST0052 | D2: PRD0200 | E2: STR037 | F2: EMP0276 | G2: 1 | H2: 749.84 | I2: 10 | J2: 74.98 | K2: 5 | L2: 33.74 | M2: 708.6 | N2: 496.67 | O2: =(M2-N2-L2) -> 178.19 | P2: UPI | Q2: =TRIM(CLEAN(P2)) -> UPI | R2: Offline | S2: Not Returned | T2: 18:16 | U2: Weekday | V2: =TEXT(tblSales[[#This Row],[Invoice Date]],"mmm") -> Dec | W2: =MONTH(tblSales[[#This Row],[Invoice Date]]) -> 12 | X2: =YEAR(tblSales[[#This Row],[Invoice Date]]) -> 2024 | Y2: =TEXT(tblSales[[#This Row],[Invoice Date]],"mmm-yyyy") -> Dec-2024 | Z2: =_xlfn.XLOOKUP(tblSales[[#This Row],[Product_ID]],Products!$A:$A,Products!$C:$C,"Women Dresses") -> Women Kurtis | AA2: =_xlfn.XLOOKUP(tblSales[[#This Row],[Product_ID]],Products!$A:$A,Products!$D:$D,"Unknown") -> A-Line Kurti | AB2: =_xlfn.XLOOKUP(tblSales[[#This Row],[Product_ID]],Products!$A:$A,Products!$E:$E,"Unknown") -> Pepe Jeans | AC2: =_xlfn.XLOOKUP(tblSales[[#This Row],[Store_ID]],Stores!$A:$A,Stores!$B:$B,"Unknown") -> TrendMart Vijayawada High Street | AD2: =_xlfn.XLOOKUP(tblSales[[#This Row],[Store_ID]],Stores!$A:$A,Stores!$E:$E,"Unknown") -> South Zone 3 | AE2: =_xlfn.XLOOKUP(tblSales[[#This Row],[Customer_ID]],Customers!$A:$A,Customers!$B:$B,"Unknown") -> Dhruv Achari | AF2: =_xlfn.XLOOKUP(tblSales[[#This Row],[Customer_ID]],Customers!$A:$A,Customers!$J:$J,"Unknown") -> Regular | AG2: =_xlfn.XLOOKUP(tblSales[[#This Row],[Employee_ID]],Employees!$A:$A,Employees!$B:$B,"Unknown") -> Manoj Ramachandran | AH2: =IF(MONTH(tblSales[[#This Row],[Invoice Date]])>=4,MONTH(tblSales[[#This Row],[Invoice Date]]),MONTH(tblSales[[#This Row],[Invoice Date]])+12) -> 12 | AI2: =DATE(YEAR(tblSales[[#This Row],[Invoice Date]]),MONTH(tblSales[[#This Row],[Invoice Date]]),1) -> 45627 | AJ2: =_xlfn.XLOOKUP(tblSales[[#This Row],[Product_ID]],Products!$A:$A,Products!$B:$B,"Unknown") -> Pepe Jeans A-Line Kurti White | AK2: =IFERROR(tblSales[[#This Row],[Profit]]/tblSales[[#This Row],[Sales Amount]],0) -> 0.25146768 | AL2: =IF(tblSales[[#This Row],[Discount %]]<=5,"0-5%", IF(tblSales[[#This Row],[Discount %]]<=10,"5-10%", IF(tblSales[[#This Row],[Discount %]]<=15,"10-15%", IF(tblSales[[#This Row],[Discount %]]<=20,"15-20%","20%+")))) -> 5-10%
A3: INV100002 | B3: 45578 | C3: CUST0463 | D3: PRD0245 | E3: STR102 | F3: EMP0156 | G3: 2 | H3: 909.55 | I3: 25 | J3: 454.77 | K3: 5 | L3: 68.22 | M3: 1432.55 | N3: 984.22 | O3: =(M3-N3-L3) -> 380.11 | P3: Debit Card | Q3: =TRIM(CLEAN(P3)) -> Debit Card | R3: Online | S3: Not Returned | T3: 13:25 | U3: Weekend | V3: =TEXT(tblSales[[#This Row],[Invoice Date]],"mmm") -> Oct | W3: =MONTH(tblSales[[#This Row],[Invoice Date]]) -> 10 | X3: =YEAR(tblSales[[#This Row],[Invoice Date]]) -> 2024 | Y3: =TEXT(tblSales[[#This Row],[Invoice Date]],"mmm-yyyy") -> Oct-2024 | Z3: =_xlfn.XLOOKUP(tblSales[[#This Row],[Product_ID]],Products!$A:$A,Products!$C:$C,"Women Dresses") -> Men T-Shirts | AA3: =_xlfn.XLOOKUP(tblSales[[#This Row],[Product_ID]],Products!$A:$A,Products!$D:$D,"Unknown") -> Round Neck | AB3: =_xlfn.XLOOKUP(tblSales[[#This Row],[Product_ID]],Products!$A:$A,Products!$E:$E,"Unknown") -> Reebok | AC3: =_xlfn.XLOOKUP(tblSales[[#This Row],[Store_ID]],Stores!$A:$A,Stores!$B:$B,"Unknown") -> TrendMart Tirunelveli High Street | AD3: =_xlfn.XLOOKUP(tblSales[[#This Row],[Store_ID]],Stores!$A:$A,Stores!$E:$E,"Unknown") -> South Zone 1 | AE3: =_xlfn.XLOOKUP(tblSales[[#This Row],[Customer_ID]],Customers!$A:$A,Customers!$B:$B,"Unknown") -> Ashok Menon | AF3: =_xlfn.XLOOKUP(tblSales[[#This Row],[Customer_ID]],Customers!$A:$A,Customers!$J:$J,"Unknown") -> Regular | AG3: =_xlfn.XLOOKUP(tblSales[[#This Row],[Employee_ID]],Employees!$A:$A,Employees!$B:$B,"Unknown") -> Deepthi Iyengar | AH3: =IF(MONTH(tblSales[[#This Row],[Invoice Date]])>=4,MONTH(tblSales[[#This Row],[Invoice Date]]),MONTH(tblSales[[#This Row],[Invoice Date]])+12) -> 10 | AI3: =DATE(YEAR(tblSales[[#This Row],[Invoice Date]]),MONTH(tblSales[[#This Row],[Invoice Date]]),1) -> 45566 | AJ3: =_xlfn.XLOOKUP(tblSales[[#This Row],[Product_ID]],Products!$A:$A,Products!$B:$B,"Unknown") -> Reebok Round Neck Sky Blue | AK3: =IFERROR(tblSales[[#This Row],[Profit]]/tblSales[[#This Row],[Sales Amount]],0) -> 0.26533803 | AL3: =IF(tblSales[[#This Row],[Discount %]]<=5,"0-5%", IF(tblSales[[#This Row],[Discount %]]<=10,"5-10%", IF(tblSales[[#This Row],[Discount %]]<=15,"10-15%", IF(tblSales[[#This Row],[Discount %]]<=20,"15-20%","20%+")))) -> 20%+
A4: INV100003 | B4: 45657 | C4: CUST0711 | D4: PRD0065 | E4: STR011 | F4: EMP0223 | G4: 2 | H4: 3872.21 | I4: 0 | J4: 0 | K4: 12 | L4: 929.33 | M4: 8673.75 | N4: 5267.12 | O4: =(M4-N4-L4) -> 2477.3 | P4: Debit Card | Q4: =TRIM(CLEAN(P4)) -> Debit Card | R4: Online | S4: Not Returned | T4: 21:10 | U4: Weekday | V4: =TEXT(tblSales[[#This Row],[Invoice Date]],"mmm") -> Dec | W4: =MONTH(tblSales[[#This Row],[Invoice Date]]) -> 12 | X4: =YEAR(tblSales[[#This Row],[Invoice Date]]) -> 2024 | Y4: =TEXT(tblSales[[#This Row],[Invoice Date]],"mmm-yyyy") -> Dec-2024 | Z4: =_xlfn.XLOOKUP(tblSales[[#This Row],[Product_ID]],Products!$A:$A,Products!$C:$C,"Women Dresses") -> Women Sarees | AA4: =_xlfn.XLOOKUP(tblSales[[#This Row],[Product_ID]],Products!$A:$A,Products!$D:$D,"Unknown") -> Georgette Saree | AB4: =_xlfn.XLOOKUP(tblSales[[#This Row],[Product_ID]],Products!$A:$A,Products!$E:$E,"Unknown") -> Westside | AC4: =_xlfn.XLOOKUP(tblSales[[#This Row],[Store_ID]],Stores!$A:$A,Stores!$B:$B,"Unknown") -> TrendMart Tirupati Standard | AD4: =_xlfn.XLOOKUP(tblSales[[#This Row],[Store_ID]],Stores!$A:$A,Stores!$E:$E,"Unknown") -> South Zone 3 | AE4: =_xlfn.XLOOKUP(tblSales[[#This Row],[Customer_ID]],Customers!$A:$A,Customers!$B:$B,"Unknown") -> Deepthi Sundaram | AF4: =_xlfn.XLOOKUP(tblSales[[#This Row],[Customer_ID]],Customers!$A:$A,Customers!$J:$J,"Unknown") -> Silver | AG4: =_xlfn.XLOOKUP(tblSales[[#This Row],[Employee_ID]],Employees!$A:$A,Employees!$B:$B,"Unknown") -> Meena Krishnan | AH4: =IF(MONTH(tblSales[[#This Row],[Invoice Date]])>=4,MONTH(tblSales[[#This Row],[Invoice Date]]),MONTH(tblSales[[#This Row],[Invoice Date]])+12) -> 12 | AI4: =DATE(YEAR(tblSales[[#This Row],[Invoice Date]]),MONTH(tblSales[[#This Row],[Invoice Date]]),1) -> 45627 | AJ4: =_xlfn.XLOOKUP(tblSales[[#This Row],[Product_ID]],Products!$A:$A,Products!$B:$B,"Unknown") -> Westside Georgette Saree White | AK4: =IFERROR(tblSales[[#This Row],[Profit]]/tblSales[[#This Row],[Sales Amount]],0) -> 0.28560888 | AL4: =IF(tblSales[[#This Row],[Discount %]]<=5,"0-5%", IF(tblSales[[#This Row],[Discount %]]<=10,"5-10%", IF(tblSales[[#This Row],[Discount %]]<=15,"10-15%", IF(tblSales[[#This Row],[Discount %]]<=20,"15-20%","20%+")))) -> 0-5%
A5: INV100004 | B5: 45437 | C5: CUST0466 | D5: PRD0224 | E5: STR078 | F5: EMP0170 | G5: 4 | H5: 4857.75 | I5: 20 | J5: 3886.2 | K5: 12 | L5: 1865.38 | M5: 17410.18 | N5: 13483.2 | O5: =(M5-N5-L5) -> 2061.6 | P5: UPI | Q5: =TRIM(CLEAN(P5)) -> UPI | R5: Online | S5: Not Returned | T5: 13:45 | U5: Weekend | V5: =TEXT(tblSales[[#This Row],[Invoice Date]],"mmm") -> May | W5: =MONTH(tblSales[[#This Row],[Invoice Date]]) -> 5 | X5: =YEAR(tblSales[[#This Row],[Invoice Date]]) -> 2024 | Y5: =TEXT(tblSales[[#This Row],[Invoice Date]],"mmm-yyyy") -> May-2024 | Z5: =_xlfn.XLOOKUP(tblSales[[#This Row],[Product_ID]],Products!$A:$A,Products!$C:$C,"Women Dresses") -> Women Sarees | AA5: =_xlfn.XLOOKUP(tblSales[[#This Row],[Product_ID]],Products!$A:$A,Products!$D:$D,"Unknown") -> Printed Saree | AB5: =_xlfn.XLOOKUP(tblSales[[#This Row],[Product_ID]],Products!$A:$A,Products!$E:$E,"Unknown") -> Max Fashion | AC5: =_xlfn.XLOOKUP(tblSales[[#This Row],[Store_ID]],Stores!$A:$A,Stores!$B:$B,"Unknown") -> TrendMart Vellore Standard | AD5: =_xlfn.XLOOKUP(tblSales[[#This Row],[Store_ID]],Stores!$A:$A,Stores!$E:$E,"Unknown") -> South Zone 1 | AE5: =_xlfn.XLOOKUP(tblSales[[#This Row],[Customer_ID]],Customers!$A:$A,Customers!$B:$B,"Unknown") -> Manoj Varma | AF5: =_xlfn.XLOOKUP(tblSales[[#This Row],[Customer_ID]],Customers!$A:$A,Customers!$J:$J,"Unknown") -> Regular | AG5: =_xlfn.XLOOKUP(tblSales[[#This Row],[Employee_ID]],Employees!$A:$A,Employees!$B:$B,"Unknown") -> Jyothi Prasad | AH5: =IF(MONTH(tblSales[[#This Row],[Invoice Date]])>=4,MONTH(tblSales[[#This Row],[Invoice Date]]),MONTH(tblSales[[#This Row],[Invoice Date]])+12) -> 5 | AI5: =DATE(YEAR(tblSales[[#This Row],[Invoice Date]]),MONTH(tblSales[[#This Row],[Invoice Date]]),1) -> 45413 | AJ5: =_xlfn.XLOOKUP(tblSales[[#This Row],[Product_ID]],Products!$A:$A,Products!$B:$B,"Unknown") -> Max Fashion Printed Saree Brown | AK5: =IFERROR(tblSales[[#This Row],[Profit]]/tblSales[[#This Row],[Sales Amount]],0) -> 0.11841348 | AL5: =IF(tblSales[[#This Row],[Discount %]]<=5,"0-5%", IF(tblSales[[#This Row],[Discount %]]<=10,"5-10%", IF(tblSales[[#This Row],[Discount %]]<=15,"10-15%", IF(tblSales[[#This Row],[Discount %]]<=20,"15-20%","20%+")))) -> 15-20%
A6: INV100005 | B6: 45487 | C6: CUST0406 | D6: PRD0035 | E6: STR058 | F6: EMP0090 | G6: 1 | H6: 874.25 | I6: 0 | J6: 0 | K6: 5 | L6: 43.71 | M6: 917.96 | N6: 539.76 | O6: =(M6-N6-L6) -> 334.49 | P6: Credit Card | Q6: =TRIM(CLEAN(P6)) -> Credit Card | R6: Offline | S6: Not Returned | T6: 21:11 | U6: Weekend | V6: =TEXT(tblSales[[#This Row],[Invoice Date]],"mmm") -> Jul | W6: =MONTH(tblSales[[#This Row],[Invoice Date]]) -> 7 | X6: =YEAR(tblSales[[#This Row],[Invoice Date]]) -> 2024 | Y6: =TEXT(tblSales[[#This Row],[Invoice Date]],"mmm-yyyy") -> Jul-2024 | Z6: =_xlfn.XLOOKUP(tblSales[[#This Row],[Product_ID]],Products!$A:$A,Products!$C:$C,"Women Dresses") -> Women Kurtis | AA6: =_xlfn.XLOOKUP(tblSales[[#This Row],[Product_ID]],Products!$A:$A,Products!$D:$D,"Unknown") -> Printed Kurti | AB6: =_xlfn.XLOOKUP(tblSales[[#This Row],[Product_ID]],Products!$A:$A,Products!$E:$E,"Unknown") -> Reebok | AC6: =_xlfn.XLOOKUP(tblSales[[#This Row],[Store_ID]],Stores!$A:$A,Stores!$B:$B,"Unknown") -> TrendMart Thoothukudi Flagship | AD6: =_xlfn.XLOOKUP(tblSales[[#This Row],[Store_ID]],Stores!$A:$A,Stores!$E:$E,"Unknown") -> South Zone 1 | AE6: =_xlfn.XLOOKUP(tblSales[[#This Row],[Customer_ID]],Customers!$A:$A,Customers!$B:$B,"Unknown") -> Gayathri Srinivasan | AF6: =_xlfn.XLOOKUP(tblSales[[#This Row],[Customer_ID]],Customers!$A:$A,Customers!$J:$J,"Unknown") -> Regular | AG6: =_xlfn.XLOOKUP(tblSales[[#This Row],[Employee_ID]],Employees!$A:$A,Employees!$B:$B,"Unknown") -> Padma Gounder | AH6: =IF(MONTH(tblSales[[#This Row],[Invoice Date]])>=4,MONTH(tblSales[[#This Row],[Invoice Date]]),MONTH(tblSales[[#This Row],[Invoice Date]])+12) -> 7 | AI6: =DATE(YEAR(tblSales[[#This Row],[Invoice Date]]),MONTH(tblSales[[#This Row],[Invoice Date]]),1) -> 45474 | AJ6: =_xlfn.XLOOKUP(tblSales[[#This Row],[Product_ID]],Products!$A:$A,Products!$B:$B,"Unknown") -> Reebok Printed Kurti Wine | AK6: =IFERROR(tblSales[[#This Row],[Profit]]/tblSales[[#This Row],[Sales Amount]],0) -> 0.36438407 | AL6: =IF(tblSales[[#This Row],[Discount %]]<=5,"0-5%", IF(tblSales[[#This Row],[Discount %]]<=10,"5-10%", IF(tblSales[[#This Row],[Discount %]]<=15,"10-15%", IF(tblSales[[#This Row],[Discount %]]<=20,"15-20%","20%+")))) -> 0-5%
A7: INV100006 | B7: 45704 | C7: CUST0084 | D7: PRD0199 | E7: STR074 | F7: EMP0204 | G7: 2 | H7: 3390.61 | I7: 30 | J7: 2034.37 | K7: 12 | L7: 569.62 | M7: 5316.47 | N7: 4849.24 | O7: =(M7-N7-L7) -> -102.39 | P7: Credit Card | Q7: =TRIM(CLEAN(P7)) -> Credit Card | R7: Offline | S7: Not Returned | T7: 10:24 | U7: Weekend | V7: =TEXT(tblSales[[#This Row],[Invoice Date]],"mmm") -> Feb | W7: =MONTH(tblSales[[#This Row],[Invoice Date]]) -> 2 | X7: =YEAR(tblSales[[#This Row],[Invoice Date]]) -> 2025 | Y7: =TEXT(tblSales[[#This Row],[Invoice Date]],"mmm-yyyy") -> Feb-2025 | Z7: =_xlfn.XLOOKUP(tblSales[[#This Row],[Product_ID]],Products!$A:$A,Products!$C:$C,"Women Dresses") -> Footwear | AA7: =_xlfn.XLOOKUP(tblSales[[#This Row],[Product_ID]],Products!$A:$A,Products!$D:$D,"Unknown") -> Formal Shoes | AB7: =_xlfn.XLOOKUP(tblSales[[#This Row],[Product_ID]],Products!$A:$A,Products!$E:$E,"Unknown") -> US Polo Assn | AC7: =_xlfn.XLOOKUP(tblSales[[#This Row],[Store_ID]],Stores!$A:$A,Stores!$B:$B,"Unknown") -> TrendMart Kurnool High Street | AD7: =_xlfn.XLOOKUP(tblSales[[#This Row],[Store_ID]],Stores!$A:$A,Stores!$E:$E,"Unknown") -> South Zone 3 | AE7: =_xlfn.XLOOKUP(tblSales[[#This Row],[Customer_ID]],Customers!$A:$A,Customers!$B:$B,"Unknown") -> Hari Kamath | AF7: =_xlfn.XLOOKUP(tblSales[[#This Row],[Customer_ID]],Customers!$A:$A,Customers!$J:$J,"Unknown") -> Platinum | AG7: =_xlfn.XLOOKUP(tblSales[[#This Row],[Employee_ID]],Employees!$A:$A,Employees!$B:$B,"Unknown") -> Rahul Krishnan | AH7: =IF(MONTH(tblSales[[#This Row],[Invoice Date]])>=4,MONTH(tblSales[[#This Row],[Invoice Date]]),MONTH(tblSales[[#This Row],[Invoice Date]])+12) -> 14 | AI7: =DATE(YEAR(tblSales[[#This Row],[Invoice Date]]),MONTH(tblSales[[#This Row],[Invoice Date]]),1) -> 45689 | AJ7: =_xlfn.XLOOKUP(tblSales[[#This Row],[Product_ID]],Products!$A:$A,Products!$B:$B,"Unknown") -> US Polo Assn Formal Shoes Red | AK7: =IFERROR(tblSales[[#This Row],[Profit]]/tblSales[[#This Row],[Sales Amount]],0) -> -0.01925902 | AL7: =IF(tblSales[[#This Row],[Discount %]]<=5,"0-5%", IF(tblSales[[#This Row],[Discount %]]<=10,"5-10%", IF(tblSales[[#This Row],[Discount %]]<=15,"10-15%", IF(tblSales[[#This Row],[Discount %]]<=20,"15-20%","20%+")))) -> 20%+
A8: INV100007 | B8: 45457 | C8: CUST0714 | D8: PRD0040 | E8: STR062 | F8: EMP0215 | G8: 4 | H8: 1474.99 | I8: 0 | J8: 0 | K8: 12 | L8: 708 | M8: 6607.96 | N8: 4594.64 | O8: =(M8-N8-L8) -> 1305.32 | P8: Cash | Q8: =TRIM(CLEAN(P8)) -> Cash | R8: Offline | S8: Not Returned | T8: 20:20 | U8: Weekday | V8: =TEXT(tblSales[[#This Row],[Invoice Date]],"mmm") -> Jun | W8: =MONTH(tblSales[[#This Row],[Invoice Date]]) -> 6 | X8: =YEAR(tblSales[[#This Row],[Invoice Date]]) -> 2024 | Y8: =TEXT(tblSales[[#This Row],[Invoice Date]],"mmm-yyyy") -> Jun-2024 | Z8: =_xlfn.XLOOKUP(tblSales[[#This Row],[Product_ID]],Products!$A:$A,Products!$C:$C,"Women Dresses") -> Sportswear | AA8: =_xlfn.XLOOKUP(tblSales[[#This Row],[Product_ID]],Products!$A:$A,Products!$D:$D,"Unknown") -> Track Suit | AB8: =_xlfn.XLOOKUP(tblSales[[#This Row],[Product_ID]],Products!$A:$A,Products!$E:$E,"Unknown") -> US Polo Assn | AC8: =_xlfn.XLOOKUP(tblSales[[#This Row],[Store_ID]],Stores!$A:$A,Stores!$B:$B,"Unknown") -> TrendMart Vijayawada Standard | AD8: =_xlfn.XLOOKUP(tblSales[[#This Row],[Store_ID]],Stores!$A:$A,Stores!$E:$E,"Unknown") -> South Zone 3 | AE8: =_xlfn.XLOOKUP(tblSales[[#This Row],[Customer_ID]],Customers!$A:$A,Customers!$B:$B,"Unknown") -> Yamini Srinivasan | AF8: =_xlfn.XLOOKUP(tblSales[[#This Row],[Customer_ID]],Customers!$A:$A,Customers!$J:$J,"Unknown") -> Silver | AG8: =_xlfn.XLOOKUP(tblSales[[#This Row],[Employee_ID]],Employees!$A:$A,Employees!$B:$B,"Unknown") -> Praveen Gupta | AH8: =IF(MONTH(tblSales[[#This Row],[Invoice Date]])>=4,MONTH(tblSales[[#This Row],[Invoice Date]]),MONTH(tblSales[[#This Row],[Invoice Date]])+12) -> 6 | AI8: =DATE(YEAR(tblSales[[#This Row],[Invoice Date]]),MONTH(tblSales[[#This Row],[Invoice Date]]),1) -> 45444 | AJ8: =_xlfn.XLOOKUP(tblSales[[#This Row],[Product_ID]],Products!$A:$A,Products!$B:$B,"Unknown") -> US Polo Assn Track Suit Maroon | AK8: =IFERROR(tblSales[[#This Row],[Profit]]/tblSales[[#This Row],[Sales Amount]],0) -> 0.19753752 | AL8: =IF(tblSales[[#This Row],[Discount %]]<=5,"0-5%", IF(tblSales[[#This Row],[Discount %]]<=10,"5-10%", IF(tblSales[[#This Row],[Discount %]]<=15,"10-15%", IF(tblSales[[#This Row],[Discount %]]<=20,"15-20%","20%+")))) -> 0-5%
A9: INV100008 | B9: 45678 | C9: CUST0121 | D9: PRD0196 | E9: STR084 | F9: EMP0285 | G9: 1 | H9: 1407.12 | I9: 0 | J9: 0 | K9: 12 | L9: 168.85 | M9: 1575.97 | N9: 1067.72 | O9: =(M9-N9-L9) -> 339.4 | P9: UPI | Q9: =TRIM(CLEAN(P9)) -> UPI | R9: Offline | S9: Not Returned | T9: 21:28 | U9: Weekday | V9: =TEXT(tblSales[[#This Row],[Invoice Date]],"mmm") -> Jan | W9: =MONTH(tblSales[[#This Row],[Invoice Date]]) -> 1 | X9: =YEAR(tblSales[[#This Row],[Invoice Date]]) -> 2025 | Y9: =TEXT(tblSales[[#This Row],[Invoice Date]],"mmm-yyyy") -> Jan-2025 | Z9: =_xlfn.XLOOKUP(tblSales[[#This Row],[Product_ID]],Products!$A:$A,Products!$C:$C,"Women Dresses") -> Men Jeans | AA9: =_xlfn.XLOOKUP(tblSales[[#This Row],[Product_ID]],Products!$A:$A,Products!$D:$D,"Unknown") -> Slim Fit | AB9: =_xlfn.XLOOKUP(tblSales[[#This Row],[Product_ID]],Products!$A:$A,Products!$E:$E,"Unknown") -> Metro Shoes | AC9: =_xlfn.XLOOKUP(tblSales[[#This Row],[Store_ID]],Stores!$A:$A,Stores!$B:$B,"Unknown") -> TrendMart Tirupati High Street | AD9: =_xlfn.XLOOKUP(tblSales[[#This Row],[Store_ID]],Stores!$A:$A,Stores!$E:$E,"Unknown") -> South Zone 3 | AE9: =_xlfn.XLOOKUP(tblSales[[#This Row],[Customer_ID]],Customers!$A:$A,Customers!$B:$B,"Unknown") -> Srinivas Prasad | AF9: =_xlfn.XLOOKUP(tblSales[[#This Row],[Customer_ID]],Customers!$A:$A,Customers!$J:$J,"Unknown") -> Silver | AG9: =_xlfn.XLOOKUP(tblSales[[#This Row],[Employee_ID]],Employees!$A:$A,Employees!$B:$B,"Unknown") -> Chandran Krishnan | AH9: =IF(MONTH(tblSales[[#This Row],[Invoice Date]])>=4,MONTH(tblSales[[#This Row],[Invoice Date]]),MONTH(tblSales[[#This Row],[Invoice Date]])+12) -> 13 | AI9: =DATE(YEAR(tblSales[[#This Row],[Invoice Date]]),MONTH(tblSales[[#This Row],[Invoice Date]]),1) -> 45658 | AJ9: =_xlfn.XLOOKUP(tblSales[[#This Row],[Product_ID]],Products!$A:$A,Products!$B:$B,"Unknown") -> Metro Shoes Slim Fit Wine | AK9: =IFERROR(tblSales[[#This Row],[Profit]]/tblSales[[#This Row],[Sales Amount]],0) -> 0.21535943 | AL9: =IF(tblSales[[#This Row],[Discount %]]<=5,"0-5%", IF(tblSales[[#This Row],[Discount %]]<=10,"5-10%", IF(tblSales[[#This Row],[Discount %]]<=15,"10-15%", IF(tblSales[[#This Row],[Discount %]]<=20,"15-20%","20%+")))) -> 0-5%
A10: INV100009 | B10: 45541 | C10: CUST0782 | D10: PRD0114 | E10: STR021 | F10: EMP0001 | G10: 5 | H10: 851.61 | I10: 5 | J10: 212.9 | K10: 5 | L10: 202.26 | M10: 4247.41 | N10: 2443 | O10: =(M10-N10-L10) -> 1602.15 | P10: Debit Card | Q10: =TRIM(CLEAN(P10)) -> Debit Card | R10: Offline | S10: Not Returned | T10: 19:05 | U10: Weekday | V10: =TEXT(tblSales[[#This Row],[Invoice Date]],"mmm") -> Sep | W10: =MONTH(tblSales[[#This Row],[Invoice Date]]) -> 9 | X10: =YEAR(tblSales[[#This Row],[Invoice Date]]) -> 2024 | Y10: =TEXT(tblSales[[#This Row],[Invoice Date]],"mmm-yyyy") -> Sep-2024 | Z10: =_xlfn.XLOOKUP(tblSales[[#This Row],[Product_ID]],Products!$A:$A,Products!$C:$C,"Women Dresses") -> Accessories | AA10: =_xlfn.XLOOKUP(tblSales[[#This Row],[Product_ID]],Products!$A:$A,Products!$D:$D,"Unknown") -> Sunglasses | AB10: =_xlfn.XLOOKUP(tblSales[[#This Row],[Product_ID]],Products!$A:$A,Products!$E:$E,"Unknown") -> Arrow | AC10: =_xlfn.XLOOKUP(tblSales[[#This Row],[Store_ID]],Stores!$A:$A,Stores!$B:$B,"Unknown") -> TrendMart Kozhikode Standard | AD10: =_xlfn.XLOOKUP(tblSales[[#This Row],[Store_ID]],Stores!$A:$A,Stores!$E:$E,"Unknown") -> South Zone 1 | AE10: =_xlfn.XLOOKUP(tblSales[[#This Row],[Customer_ID]],Customers!$A:$A,Customers!$B:$B,"Unknown") -> Rahul Yadav | AF10: =_xlfn.XLOOKUP(tblSales[[#This Row],[Customer_ID]],Customers!$A:$A,Customers!$J:$J,"Unknown") -> Gold | AG10: =_xlfn.XLOOKUP(tblSales[[#This Row],[Employee_ID]],Employees!$A:$A,Employees!$B:$B,"Unknown") -> Charulatha Kumar | AH10: =IF(MONTH(tblSales[[#This Row],[Invoice Date]])>=4,MONTH(tblSales[[#This Row],[Invoice Date]]),MONTH(tblSales[[#This Row],[Invoice Date]])+12) -> 9 | AI10: =DATE(YEAR(tblSales[[#This Row],[Invoice Date]]),MONTH(tblSales[[#This Row],[Invoice Date]]),1) -> 45536 | AJ10: =_xlfn.XLOOKUP(tblSales[[#This Row],[Product_ID]],Products!$A:$A,Products!$B:$B,"Unknown") -> Arrow Sunglasses Red | AK10: =IFERROR(tblSales[[#This Row],[Profit]]/tblSales[[#This Row],[Sales Amount]],0) -> 0.37720634 | AL10: =IF(tblSales[[#This Row],[Discount %]]<=5,"0-5%", IF(tblSales[[#This Row],[Discount %]]<=10,"5-10%", IF(tblSales[[#This Row],[Discount %]]<=15,"10-15%", IF(tblSales[[#This Row],[Discount %]]<=20,"15-20%","20%+")))) -> 0-5%
A11: INV100010 | B11: 45583 | C11: CUST0429 | D11: PRD0075 | E11: STR085 | F11: EMP0090 | G11: 1 | H11: 1041.15 | I11: 0 | J11: 0 | K11: 12 | L11: 124.94 | M11: 1166.09 | N11: 692.53 | O11: =(M11-N11-L11) -> 348.62 | P11: Credit Card | Q11: =TRIM(CLEAN(P11)) -> Credit Card | R11: Offline | S11: Not Returned | T11: 10:34 | U11: Weekday | V11: =TEXT(tblSales[[#This Row],[Invoice Date]],"mmm") -> Oct | W11: =MONTH(tblSales[[#This Row],[Invoice Date]]) -> 10 | X11: =YEAR(tblSales[[#This Row],[Invoice Date]]) -> 2024 | Y11: =TEXT(tblSales[[#This Row],[Invoice Date]],"mmm-yyyy") -> Oct-2024 | Z11: =_xlfn.XLOOKUP(tblSales[[#This Row],[Product_ID]],Products!$A:$A,Products!$C:$C,"Women Dresses") -> Women Jeans | AA11: =_xlfn.XLOOKUP(tblSales[[#This Row],[Product_ID]],Products!$A:$A,Products!$D:$D,"Unknown") -> Bootcut | AB11: =_xlfn.XLOOKUP(tblSales[[#This Row],[Product_ID]],Products!$A:$A,Products!$E:$E,"Unknown") -> Sonata | AC11: =_xlfn.XLOOKUP(tblSales[[#This Row],[Store_ID]],Stores!$A:$A,Stores!$B:$B,"Unknown") -> TrendMart Nizamabad Outlet | AD11: =_xlfn.XLOOKUP(tblSales[[#This Row],[Store_ID]],Stores!$A:$A,Stores!$E:$E,"Unknown") -> South Zone 2 | AE11: =_xlfn.XLOOKUP(tblSales[[#This Row],[Customer_ID]],Customers!$A:$A,Customers!$B:$B,"Unknown") -> Nandini Gopalakrishnan | AF11: =_xlfn.XLOOKUP(tblSales[[#This Row],[Customer_ID]],Customers!$A:$A,Customers!$J:$J,"Unknown") -> Regular | AG11: =_xlfn.XLOOKUP(tblSales[[#This Row],[Employee_ID]],Employees!$A:$A,Employees!$B:$B,"Unknown") -> Padma Gounder | AH11: =IF(MONTH(tblSales[[#This Row],[Invoice Date]])>=4,MONTH(tblSales[[#This Row],[Invoice Date]]),MONTH(tblSales[[#This Row],[Invoice Date]])+12) -> 10 | AI11: =DATE(YEAR(tblSales[[#This Row],[Invoice Date]]),MONTH(tblSales[[#This Row],[Invoice Date]]),1) -> 45566 | AJ11: =_xlfn.XLOOKUP(tblSales[[#This Row],[Product_ID]],Products!$A:$A,Products!$B:$B,"Unknown") -> Sonata Bootcut Navy Blue | AK11: =IFERROR(tblSales[[#This Row],[Profit]]/tblSales[[#This Row],[Sales Amount]],0) -> 0.29896492 | AL11: =IF(tblSales[[#This Row],[Discount %]]<=5,"0-5%", IF(tblSales[[#This Row],[Discount %]]<=10,"5-10%", IF(tblSales[[#This Row],[Discount %]]<=15,"10-15%", IF(tblSales[[#This Row],[Discount %]]<=20,"15-20%","20%+")))) -> 0-5%
A12: INV100011 | B12: 45677 | C12: CUST0162 | D12: PRD0117 | E12: STR004 | F12: EMP0258 | G12: 4 | H12: 1761.12 | I12: 10 | J12: 704.45 | K12: 12 | L12: 760.8 | M12: 7100.83 | N12: 5599.4 | O12: =(M12-N12-L12) -> 740.63 | P12: Credit Card | Q12: =TRIM(CLEAN(P12)) -> Credit Card | R12: Offline | S12: Not Returned | T12: 13:20 | U12: Weekday | V12: =TEXT(tblSales[[#This Row],[Invoice Date]],"mmm") -> Jan | W12: =MONTH(tblSales[[#This Row],[Invoice Date]]) -> 1 | X12: =YEAR(tblSales[[#This Row],[Invoice Date]]) -> 2025 | Y12: =TEXT(tblSales[[#This Row],[Invoice Date]],"mmm-yyyy") -> Jan-2025 | Z12: =_xlfn.XLOOKUP(tblSales[[#This Row],[Product_ID]],Products!$A:$A,Products!$C:$C,"Women Dresses") -> Women Dresses | AA12: =_xlfn.XLOOKUP(tblSales[[#This Row],[Product_ID]],Products!$A:$A,Products!$D:$D,"Unknown") -> Shirt Dress | AB12: =_xlfn.XLOOKUP(tblSales[[#This Row],[Product_ID]],Products!$A:$A,Products!$E:$E,"Unknown") -> Nike | AC12: =_xlfn.XLOOKUP(tblSales[[#This Row],[Store_ID]],Stores!$A:$A,Stores!$B:$B,"Unknown") -> TrendMart Kalaburagi Mall Kiosk | AD12: =_xlfn.XLOOKUP(tblSales[[#This Row],[Store_ID]],Stores!$A:$A,Stores!$E:$E,"Unknown") -> South Zone 2 | AE12: =_xlfn.XLOOKUP(tblSales[[#This Row],[Customer_ID]],Customers!$A:$A,Customers!$B:$B,"Unknown") -> Tanvi Balasubramaniam | AF12: =_xlfn.XLOOKUP(tblSales[[#This Row],[Customer_ID]],Customers!$A:$A,Customers!$J:$J,"Unknown") -> Silver | AG12: =_xlfn.XLOOKUP(tblSales[[#This Row],[Employee_ID]],Employees!$A:$A,Employees!$B:$B,"Unknown") -> Preethi Singh | AH12: =IF(MONTH(tblSales[[#This Row],[Invoice Date]])>=4,MONTH(tblSales[[#This Row],[Invoice Date]]),MONTH(tblSales[[#This Row],[Invoice Date]])+12) -> 13 | AI12: =DATE(YEAR(tblSales[[#This Row],[Invoice Date]]),MONTH(tblSales[[#This Row],[Invoice Date]]),1) -> 45658 | AJ12: =_xlfn.XLOOKUP(tblSales[[#This Row],[Product_ID]],Products!$A:$A,Products!$B:$B,"Unknown") -> Nike Shirt Dress Peach | AK12: =IFERROR(tblSales[[#This Row],[Profit]]/tblSales[[#This Row],[Sales Amount]],0) -> 0.10430189 | AL12: =IF(tblSales[[#This Row],[Discount %]]<=5,"0-5%", IF(tblSales[[#This Row],[Discount %]]<=10,"5-10%", IF(tblSales[[#This Row],[Discount %]]<=15,"10-15%", IF(tblSales[[#This Row],[Discount %]]<=20,"15-20%","20%+")))) -> 5-10%
A13: INV100012 | B13: 45736 | C13: CUST0794 | D13: PRD0078 | E13: STR068 | F13: EMP0204 | G13: 1 | H13: 1019.42 | I13: 5 | J13: 50.97 | K13: 12 | L13: 116.21 | M13: 1084.66 | N13: 828.44 | O13: =(M13-N13-L13) -> 140.01 | P13: UPI | Q13: =TRIM(CLEAN(P13)) -> UPI | R13: Online | S13: Not Returned | T13: 18:28 | U13: Weekday | V13: =TEXT(tblSales[[#This Row],[Invoice Date]],"mmm") -> Mar | W13: =MONTH(tblSales[[#This Row],[Invoice Date]]) -> 3 | X13: =YEAR(tblSales[[#This Row],[Invoice Date]]) -> 2025 | Y13: =TEXT(tblSales[[#This Row],[Invoice Date]],"mmm-yyyy") -> Mar-2025 | Z13: =_xlfn.XLOOKUP(tblSales[[#This Row],[Product_ID]],Products!$A:$A,Products!$C:$C,"Women Dresses") -> Men Jeans | AA13: =_xlfn.XLOOKUP(tblSales[[#This Row],[Product_ID]],Products!$A:$A,Products!$D:$D,"Unknown") -> Regular Fit | AB13: =_xlfn.XLOOKUP(tblSales[[#This Row],[Product_ID]],Products!$A:$A,Products!$E:$E,"Unknown") -> Metro Shoes | AC13: =_xlfn.XLOOKUP(tblSales[[#This Row],[Store_ID]],Stores!$A:$A,Stores!$B:$B,"Unknown") -> TrendMart Madurai Mall Kiosk | AD13: =_xlfn.XLOOKUP(tblSales[[#This Row],[Store_ID]],Stores!$A:$A,Stores!$E:$E,"Unknown") -> South Zone 1 | AE13: =_xlfn.XLOOKUP(tblSales[[#This Row],[Customer_ID]],Customers!$A:$A,Customers!$B:$B,"Unknown") -> Rahul Gupta | AF13: =_xlfn.XLOOKUP(tblSales[[#This Row],[Customer_ID]],Customers!$A:$A,Customers!$J:$J,"Unknown") -> Silver | AG13: =_xlfn.XLOOKUP(tblSales[[#This Row],[Employee_ID]],Employees!$A:$A,Employees!$B:$B,"Unknown") -> Rahul Krishnan | AH13: =IF(MONTH(tblSales[[#This Row],[Invoice Date]])>=4,MONTH(tblSales[[#This Row],[Invoice Date]]),MONTH(tblSales[[#This Row],[Invoice Date]])+12) -> 15 | AI13: =DATE(YEAR(tblSales[[#This Row],[Invoice Date]]),MONTH(tblSales[[#This Row],[Invoice Date]]),1) -> 45717 | AJ13: =_xlfn.XLOOKUP(tblSales[[#This Row],[Product_ID]],Products!$A:$A,Products!$B:$B,"Unknown") -> Metro Shoes Regular Fit Charcoal | AK13: =IFERROR(tblSales[[#This Row],[Profit]]/tblSales[[#This Row],[Sales Amount]],0) -> 0.12908192 | AL13: =IF(tblSales[[#This Row],[Discount %]]<=5,"0-5%", IF(tblSales[[#This Row],[Discount %]]<=10,"5-10%", IF(tblSales[[#This Row],[Discount %]]<=15,"10-15%", IF(tblSales[[#This Row],[Discount %]]<=20,"15-20%","20%+")))) -> 0-5%
... A68: INV100067 | B68: 45622 | C68: CUST0746 | D68: PRD0019 | E68: STR100 | F68: EMP0141 | G68: 1 | H68: 640.02 | I68: 25 | J68: 160 | K68: 5 | L68: 24 | M68: 504.02 | N68: 413.39 | O68: =(M68-N68-L68) -> 66.63 | P68: Cash | Q68: =TRIM(CLEAN(P68)) -> Cash | R68: Online | S68: Not Returned | T68: 16:30 | U68: Weekday | V68: =TEXT(tblSales[[#This Row],[Invoice Date]],"mmm") -> Nov | W68: =MONTH(tblSales[[#This Row],[Invoice Date]]) -> 11 | X68: =YEAR(tblSales[[#This Row],[Invoice Date]]) -> 2024 | Y68: =TEXT(tblSales[[#This Row],[Invoice Date]],"mmm-yyyy") -> Nov-2024 | Z68: =_xlfn.XLOOKUP(tblSales[[#This Row],[Product_ID]],Products!$A:$A,Products!$C:$C,"Women Dresses") -> Kids Wear | AA68: =_xlfn.XLOOKUP(tblSales[[#This Row],[Product_ID]],Products!$A:$A,Products!$D:$D,"Unknown") -> Kids T-Shirt | AB68: =_xlfn.XLOOKUP(tblSales[[#This Row],[Product_ID]],Products!$A:$A,Products!$E:$E,"Unknown") -> Jack & Jones | AC68: =_xlfn.XLOOKUP(tblSales[[#This Row],[Store_ID]],Stores!$A:$A,Stores!$B:$B,"Unknown") -> TrendMart Hubballi Standard | AD68: =_xlfn.XLOOKUP(tblSales[[#This Row],[Store_ID]],Stores!$A:$A,Stores!$E:$E,"Unknown") -> South Zone 2 | AE68: =_xlfn.XLOOKUP(tblSales[[#This Row],[Customer_ID]],Customers!$A:$A,Customers!$B:$B,"Unknown") -> Pandian Venkatesan | AF68: =_xlfn.XLOOKUP(tblSales[[#This Row],[Customer_ID]],Customers!$A:$A,Customers!$J:$J,"Unknown") -> Silver | AG68: =_xlfn.XLOOKUP(tblSales[[#This Row],[Employee_ID]],Employees!$A:$A,Employees!$B:$B,"Unknown") -> Dhruv Mishra | AH68: =IF(MONTH(tblSales[[#This Row],[Invoice Date]])>=4,MONTH(tblSales[[#This Row],[Invoice Date]]),MONTH(tblSales[[#This Row],[Invoice Date]])+12) -> 11 | AI68: =DATE(YEAR(tblSales[[#This Row],[Invoice Date]]),MONTH(tblSales[[#This Row],[Invoice Date]]),1) -> 45597 | AJ68: =_xlfn.XLOOKUP(tblSales[[#This Row],[Product_ID]],Products!$A:$A,Products!$B:$B,"Unknown") -> Sonata Girls Frock Cream | AK68: =IFERROR(tblSales[[#This Row],[Profit]]/tblSales[[#This Row],[Sales Amount]],0) -> 0.13219714 | AL68: =IF(tblSales[[#This Row],[Discount %]]<=5,"0-5%", IF(tblSales[[#This Row],[Discount %]]<=10,"5-10%", IF(tblSales[[#This Row],[Discount %]]<=15,"10-15%", IF(tblSales[[#This Row],[Discount %]]<=20,"15-20%","20%+")))) -> 20%+
A69: INV100068 | B69: 45541 | C69: CUST0583 | D69: PRD0134 | E69: STR112 | F69: EMP0203 | G69: 0 | H69: 924.29 | I69: 0 | J69: 0 | K69: 5 | L69: 0 | M69: 0 | N69: 0 | O69: 0 | P69: EMI | Q69: =TRIM(CLEAN(P69)) -> EMI | R69: Online | S69: Not Returned | T69: 18:42 | U69: Weekday | V69: =TEXT(tblSales[[#This Row],[Invoice Date]],"mmm") -> Sep | W69: =MONTH(tblSales[[#This Row],[Invoice Date]]) -> 9 | X69: =YEAR(tblSales[[#This Row],[Invoice Date]]) -> 2024 | Y69: =TEXT(tblSales[[#This Row],[Invoice Date]],"mmm-yyyy") -> Sep-2024 | Z69: =_xlfn.XLOOKUP(tblSales[[#This Row],[Product_ID]],Products!$A:$A,Products!$C:$C,"Women Dresses") -> Women Dresses | AA69: =_xlfn.XLOOKUP(tblSales[[#This Row],[Product_ID]],Products!$A:$A,Products!$D:$D,"Unknown") -> Maxi Dress | AB69: =_xlfn.XLOOKUP(tblSales[[#This Row],[Product_ID]],Products!$A:$A,Products!$E:$E,"Unknown") -> Jack & Jones | AC69: =_xlfn.XLOOKUP(tblSales[[#This Row],[Store_ID]],Stores!$A:$A,Stores!$B:$B,"Unknown") -> TrendMart Guntur Outlet | AD69: =_xlfn.XLOOKUP(tblSales[[#This Row],[Store_ID]],Stores!$A:$A,Stores!$E:$E,"Unknown") -> South Zone 3 | AE69: =_xlfn.XLOOKUP(tblSales[[#This Row],[Customer_ID]],Customers!$A:$A,Customers!$B:$B,"Unknown") -> Feroz Naicker | AF69: =_xlfn.XLOOKUP(tblSales[[#This Row],[Customer_ID]],Customers!$A:$A,Customers!$J:$J,"Unknown") -> Silver | AG69: =_xlfn.XLOOKUP(tblSales[[#This Row],[Employee_ID]],Employees!$A:$A,Employees!$B:$B,"Unknown") -> Rani Mishra | AH69: =IF(MONTH(tblSales[[#This Row],[Invoice Date]])>=4,MONTH(tblSales[[#This Row],[Invoice Date]]),MONTH(tblSales[[#This Row],[Invoice Date]])+12) -> 9 | AI69: =DATE(YEAR(tblSales[[#This Row],[Invoice Date]]),MONTH(tblSales[[#This Row],[Invoice Date]]),1) -> 45536 | AJ69: =_xlfn.XLOOKUP(tblSales[[#This Row],[Product_ID]],Products!$A:$A,Products!$B:$B,"Unknown") -> Jack & Jones Maxi Dress Maroon | AK69: =IFERROR(tblSales[[#This Row],[Profit]]/tblSales[[#This Row],[Sales Amount]],0) -> 0 | AL69: =IF(tblSales[[#This Row],[Discount %]]<=5,"0-5%", IF(tblSales[[#This Row],[Discount %]]<=10,"5-10%", IF(tblSales[[#This Row],[Discount %]]<=15,"10-15%", IF(tblSales[[#This Row],[Discount %]]<=20,"15-20%","20%+")))) -> 0-5%
A70: INV100069 | B70: 45622 | C70: CUST0422 | D70: PRD0117 | E70: STR088 | F70: EMP0204 | G70: 2 | H70: 1714.04 | I70: 10 | J70: 342.81 | K70: 12 | L70: 370.23 | M70: 3455.5 | N70: 2799.7 | O70: =(M70-N70-L70) -> 285.57 | P70: Cash | Q70: =TRIM(CLEAN(P70)) -> Cash | R70: Online | S70: Not Returned | T70: 19:44 | U70: Weekday | V70: =TEXT(tblSales[[#This Row],[Invoice Date]],"mmm") -> Nov | W70: =MONTH(tblSales[[#This Row],[Invoice Date]]) -> 11 | X70: =YEAR(tblSales[[#This Row],[Invoice Date]]) -> 2024 | Y70: =TEXT(tblSales[[#This Row],[Invoice Date]],"mmm-yyyy") -> Nov-2024 | Z70: =_xlfn.XLOOKUP(tblSales[[#This Row],[Product_ID]],Products!$A:$A,Products!$C:$C,"Women Dresses") -> Women Dresses | AA70: =_xlfn.XLOOKUP(tblSales[[#This Row],[Product_ID]],Products!$A:$A,Products!$D:$D,"Unknown") -> Shirt Dress | AB70: =_xlfn.XLOOKUP(tblSales[[#This Row],[Product_ID]],Products!$A:$A,Products!$E:$E,"Unknown") -> Nike | AC70: =_xlfn.XLOOKUP(tblSales[[#This Row],[Store_ID]],Stores!$A:$A,Stores!$B:$B,"Unknown") -> TrendMart Warangal High Street | AD70: =_xlfn.XLOOKUP(tblSales[[#This Row],[Store_ID]],Stores!$A:$A,Stores!$E:$E,"Unknown") -> South Zone 2 | AE70: =_xlfn.XLOOKUP(tblSales[[#This Row],[Customer_ID]],Customers!$A:$A,Customers!$B:$B,"Unknown") -> Malathi Shetty | AF70: =_xlfn.XLOOKUP(tblSales[[#This Row],[Customer_ID]],Customers!$A:$A,Customers!$J:$J,"Unknown") -> Silver | AG70: =_xlfn.XLOOKUP(tblSales[[#This Row],[Employee_ID]],Employees!$A:$A,Employees!$B:$B,"Unknown") -> Rahul Krishnan | AH70: =IF(MONTH(tblSales[[#This Row],[Invoice Date]])>=4,MONTH(tblSales[[#This Row],[Invoice Date]]),MONTH(tblSales[[#This Row],[Invoice Date]])+12) -> 11 | AI70: =DATE(YEAR(tblSales[[#This Row],[Invoice Date]]),MONTH(tblSales[[#This Row],[Invoice Date]]),1) -> 45597 | AJ70: =_xlfn.XLOOKUP(tblSales[[#This Row],[Product_ID]],Products!$A:$A,Products!$B:$B,"Unknown") -> Nike Shirt Dress Peach | AK70: =IFERROR(tblSales[[#This Row],[Profit]]/tblSales[[#This Row],[Sales Amount]],0) -> 0.082642165 | AL70: =IF(tblSales[[#This Row],[Discount %]]<=5,"0-5%", IF(tblSales[[#This Row],[Discount %]]<=10,"5-10%", IF(tblSales[[#This Row],[Discount %]]<=15,"10-15%", IF(tblSales[[#This Row],[Discount %]]<=20,"15-20%","20%+")))) -> 5-10%
A71: INV100070 | B71: 45620 | C71: CUST0613 | D71: PRD0116 | E71: STR096 | F71: EMP0215 | G71: 3 | H71: 1579.45 | I71: 15 | J71: 710.75 | K71: 12 | L71: 483.31 | M71: 4510.91 | N71: 3146.13 | O71: =(M71-N71-L71) -> 881.47 | P71: Debit Card | Q71: =TRIM(CLEAN(P71)) -> Debit Card | R71: Online | S71: Not Returned | T71: 21:51 | U71: Weekend | V71: =TEXT(tblSales[[#This Row],[Invoice Date]],"mmm") -> Nov | W71: =MONTH(tblSales[[#This Row],[Invoice Date]]) -> 11 | X71: =YEAR(tblSales[[#This Row],[Invoice Date]]) -> 2024 | Y71: =TEXT(tblSales[[#This Row],[Invoice Date]],"mmm-yyyy") -> Nov-2024 | Z71: =_xlfn.XLOOKUP(tblSales[[#This Row],[Product_ID]],Products!$A:$A,Products!$C:$C,"Women Dresses") -> Women Jeans | AA71: =_xlfn.XLOOKUP(tblSales[[#This Row],[Product_ID]],Products!$A:$A,Products!$D:$D,"Unknown") -> Bootcut | AB71: =_xlfn.XLOOKUP(tblSales[[#This Row],[Product_ID]],Products!$A:$A,Products!$E:$E,"Unknown") -> Woodland | AC71: =_xlfn.XLOOKUP(tblSales[[#This Row],[Store_ID]],Stores!$A:$A,Stores!$B:$B,"Unknown") -> TrendMart Mangaluru Mall Kiosk | AD71: =_xlfn.XLOOKUP(tblSales[[#This Row],[Store_ID]],Stores!$A:$A,Stores!$E:$E,"Unknown") -> South Zone 2 | AE71: =_xlfn.XLOOKUP(tblSales[[#This Row],[Customer_ID]],Customers!$A:$A,Customers!$B:$B,"Unknown") -> Usha Krishnan | AF71: =_xlfn.XLOOKUP(tblSales[[#This Row],[Customer_ID]],Customers!$A:$A,Customers!$J:$J,"Unknown") -> Gold | AG71: =_xlfn.XLOOKUP(tblSales[[#This Row],[Employee_ID]],Employees!$A:$A,Employees!$B:$B,"Unknown") -> Praveen Gupta | AH71: =IF(MONTH(tblSales[[#This Row],[Invoice Date]])>=4,MONTH(tblSales[[#This Row],[Invoice Date]]),MONTH(tblSales[[#This Row],[Invoice Date]])+12) -> 11 | AI71: =DATE(YEAR(tblSales[[#This Row],[Invoice Date]]),MONTH(tblSales[[#This Row],[Invoice Date]]),1) -> 45597 | AJ71: =_xlfn.XLOOKUP(tblSales[[#This Row],[Product_ID]],Products!$A:$A,Products!$B:$B,"Unknown") -> Woodland Bootcut Peach | AK71: =IFERROR(tblSales[[#This Row],[Profit]]/tblSales[[#This Row],[Sales Amount]],0) -> 0.19540847 | AL71: =IF(tblSales[[#This Row],[Discount %]]<=5,"0-5%", IF(tblSales[[#This Row],[Discount %]]<=10,"5-10%", IF(tblSales[[#This Row],[Discount %]]<=15,"10-15%", IF(tblSales[[#This Row],[Discount %]]<=20,"15-20%","20%+")))) -> 10-15%
A72: INV100071 | B72: 45426 | C72: CUST0131 | D72: PRD0115 | E72: STR016 | F72: EMP0258 | G72: 1 | H72: 1632.35 | I72: 5 | J72: 81.62 | K72: 12 | L72: 186.09 | M72: 1736.82 | N72: 1140.9 | O72: =(M72-N72-L72) -> 409.83 | P72: Net Banking | Q72: =TRIM(CLEAN(P72)) -> Net Banking | R72: Online | S72: Not Returned | T72: 19:45 | U72: Weekday | V72: =TEXT(tblSales[[#This Row],[Invoice Date]],"mmm") -> May | W72: =MONTH(tblSales[[#This Row],[Invoice Date]]) -> 5 | X72: =YEAR(tblSales[[#This Row],[Invoice Date]]) -> 2024 | Y72: =TEXT(tblSales[[#This Row],[Invoice Date]],"mmm-yyyy") -> May-2024 | Z72: =_xlfn.XLOOKUP(tblSales[[#This Row],[Product_ID]],Products!$A:$A,Products!$C:$C,"Women Dresses") -> Women Dresses | AA72: =_xlfn.XLOOKUP(tblSales[[#This Row],[Product_ID]],Products!$A:$A,Products!$D:$D,"Unknown") -> Bodycon Dress | AB72: =_xlfn.XLOOKUP(tblSales[[#This Row],[Product_ID]],Products!$A:$A,Products!$E:$E,"Unknown") -> Reebok | AC72: =_xlfn.XLOOKUP(tblSales[[#This Row],[Store_ID]],Stores!$A:$A,Stores!$B:$B,"Unknown") -> TrendMart Visakhapatnam Flagship | AD72: =_xlfn.XLOOKUP(tblSales[[#This Row],[Store_ID]],Stores!$A:$A,Stores!$E:$E,"Unknown") -> South Zone 3 | AE72: =_xlfn.XLOOKUP(tblSales[[#This Row],[Customer_ID]],Customers!$A:$A,Customers!$B:$B,"Unknown") -> Jyothi Achari | AF72: =_xlfn.XLOOKUP(tblSales[[#This Row],[Customer_ID]],Customers!$A:$A,Customers!$J:$J,"Unknown") -> Regular | AG72: =_xlfn.XLOOKUP(tblSales[[#This Row],[Employee_ID]],Employees!$A:$A,Employees!$B:$B,"Unknown") -> Preethi Singh | AH72: =IF(MONTH(tblSales[[#This Row],[Invoice Date]])>=4,MONTH(tblSales[[#This Row],[Invoice Date]]),MONTH(tblSales[[#This Row],[Invoice Date]])+12) -> 5 | AI72: =DATE(YEAR(tblSales[[#This Row],[Invoice Date]]),MONTH(tblSales[[#This Row],[Invoice Date]]),1) -> 45413 | AJ72: =_xlfn.XLOOKUP(tblSales[[#This Row],[Product_ID]],Products!$A:$A,Products!$B:$B,"Unknown") -> Reebok Bodycon Dress Navy Blue | AK72: =IFERROR(tblSales[[#This Row],[Profit]]/tblSales[[#This Row],[Sales Amount]],0) -> 0.23596573 | AL72: =IF(tblSales[[#This Row],[Discount %]]<=5,"0-5%", IF(tblSales[[#This Row],[Discount %]]<=10,"5-10%", IF(tblSales[[#This Row],[Discount %]]<=15,"10-15%", IF(tblSales[[#This Row],[Discount %]]<=20,"15-20%","20%+")))) -> 0-5%
A73: INV100072 | B73: 45586 | C73: CUST0338 | D73: PRD0034 | E73: STR074 | F73: EMP0149 | G73: 0 | H73: 413.58 | I73: 0 | J73: 0 | K73: 5 | L73: 0 | M73: 0 | N73: 0 | O73: 0 | P73: EMI | Q73: =TRIM(CLEAN(P73)) -> EMI | R73: Online | S73: Not Returned | T73: 21:44 | U73: Weekday | V73: =TEXT(tblSales[[#This Row],[Invoice Date]],"mmm") -> Oct | W73: =MONTH(tblSales[[#This Row],[Invoice Date]]) -> 10 | X73: =YEAR(tblSales[[#This Row],[Invoice Date]]) -> 2024 | Y73: =TEXT(tblSales[[#This Row],[Invoice Date]],"mmm-yyyy") -> Oct-2024 | Z73: =_xlfn.XLOOKUP(tblSales[[#This Row],[Product_ID]],Products!$A:$A,Products!$C:$C,"Women Dresses") -> Belts | AA73: =_xlfn.XLOOKUP(tblSales[[#This Row],[Product_ID]],Products!$A:$A,Products!$D:$D,"Unknown") -> Casual Belt | AB73: =_xlfn.XLOOKUP(tblSales[[#This Row],[Product_ID]],Products!$A:$A,Products!$E:$E,"Unknown") -> Nike | AC73: =_xlfn.XLOOKUP(tblSales[[#This Row],[Store_ID]],Stores!$A:$A,Stores!$B:$B,"Unknown") -> TrendMart Kurnool High Street | AD73: =_xlfn.XLOOKUP(tblSales[[#This Row],[Store_ID]],Stores!$A:$A,Stores!$E:$E,"Unknown") -> South Zone 3 | AE73: =_xlfn.XLOOKUP(tblSales[[#This Row],[Customer_ID]],Customers!$A:$A,Customers!$B:$B,"Unknown") -> Vijay Prasad | AF73: =_xlfn.XLOOKUP(tblSales[[#This Row],[Customer_ID]],Customers!$A:$A,Customers!$J:$J,"Unknown") -> Silver | AG73: =_xlfn.XLOOKUP(tblSales[[#This Row],[Employee_ID]],Employees!$A:$A,Employees!$B:$B,"Unknown") -> Vasanthi Kamath | AH73: =IF(MONTH(tblSales[[#This Row],[Invoice Date]])>=4,MONTH(tblSales[[#This Row],[Invoice Date]]),MONTH(tblSales[[#This Row],[Invoice Date]])+12) -> 10 | AI73: =DATE(YEAR(tblSales[[#This Row],[Invoice Date]]),MONTH(tblSales[[#This Row],[Invoice Date]]),1) -> 45566 | AJ73: =_xlfn.XLOOKUP(tblSales[[#This Row],[Product_ID]],Products!$A:$A,Products!$B:$B,"Unknown") -> Nike Casual Belt Olive | AK73: =IFERROR(tblSales[[#This Row],[Profit]]/tblSales[[#This Row],[Sales Amount]],0) -> 0 | AL73: =IF(tblSales[[#This Row],[Discount %]]<=5,"0-5%", IF(tblSales[[#This Row],[Discount %]]<=10,"5-10%", IF(tblSales[[#This Row],[Discount %]]<=15,"10-15%", IF(tblSales[[#This Row],[Discount %]]<=20,"15-20%","20%+")))) -> 0-5%
A74: INV100073 | B74: 45693 | C74: CUST0721 | D74: PRD0082 | E74: STR110 | F74: EMP0141 | G74: 3 | H74: 2846.44 | I74: 5 | J74: 426.97 | K74: 12 | L74: 973.48 | M74: 9085.83 | N74: 6454.02 | O74: =(M74-N74-L74) -> 1658.33 | P74: Debit Card | Q74: =TRIM(CLEAN(P74)) -> Debit Card | R74: Online | S74: Not Returned | T74: 21:32 | U74: Weekday | V74: =TEXT(tblSales[[#This Row],[Invoice Date]],"mmm") -> Feb | W74: =MONTH(tblSales[[#This Row],[Invoice Date]]) -> 2 | X74: =YEAR(tblSales[[#This Row],[Invoice Date]]) -> 2025 | Y74: =TEXT(tblSales[[#This Row],[Invoice Date]],"mmm-yyyy") -> Feb-2025 | Z74: =_xlfn.XLOOKUP(tblSales[[#This Row],[Product_ID]],Products!$A:$A,Products!$C:$C,"Women Dresses") -> Handbags | AA74: =_xlfn.XLOOKUP(tblSales[[#This Row],[Product_ID]],Products!$A:$A,Products!$D:$D,"Unknown") -> Sling Bag | AB74: =_xlfn.XLOOKUP(tblSales[[#This Row],[Product_ID]],Products!$A:$A,Products!$E:$E,"Unknown") -> Libas | AC74: =_xlfn.XLOOKUP(tblSales[[#This Row],[Store_ID]],Stores!$A:$A,Stores!$B:$B,"Unknown") -> TrendMart Thoothukudi Outlet | AD74: =_xlfn.XLOOKUP(tblSales[[#This Row],[Store_ID]],Stores!$A:$A,Stores!$E:$E,"Unknown") -> South Zone 1 | AE74: =_xlfn.XLOOKUP(tblSales[[#This Row],[Customer_ID]],Customers!$A:$A,Customers!$B:$B,"Unknown") -> Kavya Singh | AF74: =_xlfn.XLOOKUP(tblSales[[#This Row],[Customer_ID]],Customers!$A:$A,Customers!$J:$J,"Unknown") -> Regular | AG74: =_xlfn.XLOOKUP(tblSales[[#This Row],[Employee_ID]],Employees!$A:$A,Employees!$B:$B,"Unknown") -> Dhruv Mishra | AH74: =IF(MONTH(tblSales[[#This Row],[Invoice Date]])>=4,MONTH(tblSales[[#This Row],[Invoice Date]]),MONTH(tblSales[[#This Row],[Invoice Date]])+12) -> 14 | AI74: =DATE(YEAR(tblSales[[#This Row],[Invoice Date]]),MONTH(tblSales[[#This Row],[Invoice Date]]),1) -> 45689 | AJ74: =_xlfn.XLOOKUP(tblSales[[#This Row],[Product_ID]],Products!$A:$A,Products!$B:$B,"Unknown") -> Libas Sling Bag Green | AK74: =IFERROR(tblSales[[#This Row],[Profit]]/tblSales[[#This Row],[Sales Amount]],0) -> 0.18251827 | AL74: =IF(tblSales[[#This Row],[Discount %]]<=5,"0-5%", IF(tblSales[[#This Row],[Discount %]]<=10,"5-10%", IF(tblSales[[#This Row],[Discount %]]<=15,"10-15%", IF(tblSales[[#This Row],[Discount %]]<=20,"15-20%","20%+")))) -> 0-5%
A75: INV100074 | B75: 45399 | C75: CUST0210 | D75: PRD0075 | E75: STR055 | F75: EMP0285 | G75: 1 | H75: 1011.81 | I75: 30 | J75: 303.54 | K75: 12 | L75: 84.99 | M75: 793.26 | N75: 692.53 | O75: =(M75-N75-L75) -> 15.74 | P75: UPI | Q75: =TRIM(CLEAN(P75)) -> UPI | R75: Offline | S75: Not Returned | T75: 16:33 | U75: Weekday | V75: =TEXT(tblSales[[#This Row],[Invoice Date]],"mmm") -> Apr | W75: =MONTH(tblSales[[#This Row],[Invoice Date]]) -> 4 | X75: =YEAR(tblSales[[#This Row],[Invoice Date]]) -> 2024 | Y75: =TEXT(tblSales[[#This Row],[Invoice Date]],"mmm-yyyy") -> Apr-2024 | Z75: =_xlfn.XLOOKUP(tblSales[[#This Row],[Product_ID]],Products!$A:$A,Products!$C:$C,"Women Dresses") -> Women Jeans | AA75: =_xlfn.XLOOKUP(tblSales[[#This Row],[Product_ID]],Products!$A:$A,Products!$D:$D,"Unknown") -> Bootcut | AB75: =_xlfn.XLOOKUP(tblSales[[#This Row],[Product_ID]],Products!$A:$A,Products!$E:$E,"Unknown") -> Sonata | AC75: =_xlfn.XLOOKUP(tblSales[[#This Row],[Store_ID]],Stores!$A:$A,Stores!$B:$B,"Unknown") -> TrendMart Nellore High Street | AD75: =_xlfn.XLOOKUP(tblSales[[#This Row],[Store_ID]],Stores!$A:$A,Stores!$E:$E,"Unknown") -> South Zone 3 | AE75: =_xlfn.XLOOKUP(tblSales[[#This Row],[Customer_ID]],Customers!$A:$A,Customers!$B:$B,"Unknown") -> Priya Pandian | AF75: =_xlfn.XLOOKUP(tblSales[[#This Row],[Customer_ID]],Customers!$A:$A,Customers!$J:$J,"Unknown") -> Regular | AG75: =_xlfn.XLOOKUP(tblSales[[#This Row],[Employee_ID]],Employees!$A:$A,Employees!$B:$B,"Unknown") -> Chandran Krishnan | AH75: =IF(MONTH(tblSales[[#This Row],[Invoice Date]])>=4,MONTH(tblSales[[#This Row],[Invoice Date]]),MONTH(tblSales[[#This Row],[Invoice Date]])+12) -> 4 | AI75: =DATE(YEAR(tblSales[[#This Row],[Invoice Date]]),MONTH(tblSales[[#This Row],[Invoice Date]]),1) -> 45383 | AJ75: =_xlfn.XLOOKUP(tblSales[[#This Row],[Product_ID]],Products!$A:$A,Products!$B:$B,"Unknown") -> Sonata Bootcut Navy Blue | AK75: =IFERROR(tblSales[[#This Row],[Profit]]/tblSales[[#This Row],[Sales Amount]],0) -> 0.01984217 | AL75: =IF(tblSales[[#This Row],[Discount %]]<=5,"0-5%", IF(tblSales[[#This Row],[Discount %]]<=10,"5-10%", IF(tblSales[[#This Row],[Discount %]]<=15,"10-15%", IF(tblSales[[#This Row],[Discount %]]<=20,"15-20%","20%+")))) -> 20%+
A76: INV100075 | B76: 45620 | C76: CUST0658 | D76: PRD0203 | E76: STR045 | F76: EMP0255 | G76: 5 | H76: 1268.61 | I76: 15 | J76: 951.46 | K76: 12 | L76: 646.99 | M76: 6038.58 | N76: 4573.6 | O76: =(M76-N76-L76) -> 817.99 | P76: Debit Card | Q76: =TRIM(CLEAN(P76)) -> Debit Card | R76: Offline | S76: Not Returned | T76: 19:17 | U76: Weekend | V76: =TEXT(tblSales[[#This Row],[Invoice Date]],"mmm") -> Nov | W76: =MONTH(tblSales[[#This Row],[Invoice Date]]) -> 11 | X76: =YEAR(tblSales[[#This Row],[Invoice Date]]) -> 2024 | Y76: =TEXT(tblSales[[#This Row],[Invoice Date]],"mmm-yyyy") -> Nov-2024 | Z76: =_xlfn.XLOOKUP(tblSales[[#This Row],[Product_ID]],Products!$A:$A,Products!$C:$C,"Women Dresses") -> Sportswear | AA76: =_xlfn.XLOOKUP(tblSales[[#This Row],[Product_ID]],Products!$A:$A,Products!$D:$D,"Unknown") -> Sports T-Shirt | AB76: =_xlfn.XLOOKUP(tblSales[[#This Row],[Product_ID]],Products!$A:$A,Products!$E:$E,"Unknown") -> Liberty | AC76: =_xlfn.XLOOKUP(tblSales[[#This Row],[Store_ID]],Stores!$A:$A,Stores!$B:$B,"Unknown") -> TrendMart Khammam Standard | AD76: =_xlfn.XLOOKUP(tblSales[[#This Row],[Store_ID]],Stores!$A:$A,Stores!$E:$E,"Unknown") -> South Zone 2 | AE76: =_xlfn.XLOOKUP(tblSales[[#This Row],[Customer_ID]],Customers!$A:$A,Customers!$B:$B,"Unknown") -> Kiran Gupta | AF76: =_xlfn.XLOOKUP(tblSales[[#This Row],[Customer_ID]],Customers!$A:$A,Customers!$J:$J,"Unknown") -> Gold | AG76: =_xlfn.XLOOKUP(tblSales[[#This Row],[Employee_ID]],Employees!$A:$A,Employees!$B:$B,"Unknown") -> Venkat Sharma | AH76: =IF(MONTH(tblSales[[#This Row],[Invoice Date]])>=4,MONTH(tblSales[[#This Row],[Invoice Date]]),MONTH(tblSales[[#This Row],[Invoice Date]])+12) -> 11 | AI76: =DATE(YEAR(tblSales[[#This Row],[Invoice Date]]),MONTH(tblSales[[#This Row],[Invoice Date]]),1) -> 45597 | AJ76: =_xlfn.XLOOKUP(tblSales[[#This Row],[Product_ID]],Products!$A:$A,Products!$B:$B,"Unknown") -> Liberty Sports T-Shirt Peach | AK76: =IFERROR(tblSales[[#This Row],[Profit]]/tblSales[[#This Row],[Sales Amount]],0) -> 0.13546065 | AL76: =IF(tblSales[[#This Row],[Discount %]]<=5,"0-5%", IF(tblSales[[#This Row],[Discount %]]<=10,"5-10%", IF(tblSales[[#This Row],[Discount %]]<=15,"10-15%", IF(tblSales[[#This Row],[Discount %]]<=20,"15-20%","20%+")))) -> 10-15%
A77: INV100076 | B77: 45633 | C77: CUST0636 | D77: PRD0022 | E77: STR104 | F77: EMP0086 | G77: 1 | H77: 1323.12 | I77: 0 | J77: 0 | K77: 12 | L77: 158.77 | M77: 1481.89 | N77: 767.83 | O77: =(M77-N77-L77) -> 555.29 | P77: Credit Card | Q77: =TRIM(CLEAN(P77)) -> Credit Card | R77: Offline | S77: Not Returned | T77: 11:24 | U77: Weekend | V77: =TEXT(tblSales[[#This Row],[Invoice Date]],"mmm") -> Dec | W77: =MONTH(tblSales[[#This Row],[Invoice Date]]) -> 12 | X77: =YEAR(tblSales[[#This Row],[Invoice Date]]) -> 2024 | Y77: =TEXT(tblSales[[#This Row],[Invoice Date]],"mmm-yyyy") -> Dec-2024 | Z77: =_xlfn.XLOOKUP(tblSales[[#This Row],[Product_ID]],Products!$A:$A,Products!$C:$C,"Women Dresses") -> Women Jeans | AA77: =_xlfn.XLOOKUP(tblSales[[#This Row],[Product_ID]],Products!$A:$A,Products!$D:$D,"Unknown") -> Skinny Fit | AB77: =_xlfn.XLOOKUP(tblSales[[#This Row],[Product_ID]],Products!$A:$A,Products!$E:$E,"Unknown") -> Being Human | AC77: =_xlfn.XLOOKUP(tblSales[[#This Row],[Store_ID]],Stores!$A:$A,Stores!$B:$B,"Unknown") -> TrendMart Kochi High Street | AD77: =_xlfn.XLOOKUP(tblSales[[#This Row],[Store_ID]],Stores!$A:$A,Stores!$E:$E,"Unknown") -> South Zone 1 | AE77: =_xlfn.XLOOKUP(tblSales[[#This Row],[Customer_ID]],Customers!$A:$A,Customers!$B:$B,"Unknown") -> Gayathri Gowda | AF77: =_xlfn.XLOOKUP(tblSales[[#This Row],[Customer_ID]],Customers!$A:$A,Customers!$J:$J,"Unknown") -> Regular | AG77: =_xlfn.XLOOKUP(tblSales[[#This Row],[Employee_ID]],Employees!$A:$A,Employees!$B:$B,"Unknown") -> Anil Reddy | AH77: =IF(MONTH(tblSales[[#This Row],[Invoice Date]])>=4,MONTH(tblSales[[#This Row],[Invoice Date]]),MONTH(tblSales[[#This Row],[Invoice Date]])+12) -> 12 | AI77: =DATE(YEAR(tblSales[[#This Row],[Invoice Date]]),MONTH(tblSales[[#This Row],[Invoice Date]]),1) -> 45627 | AJ77: =_xlfn.XLOOKUP(tblSales[[#This Row],[Product_ID]],Products!$A:$A,Products!$B:$B,"Unknown") -> Being Human Skinny Fit Charcoal | AK77: =IFERROR(tblSales[[#This Row],[Profit]]/tblSales[[#This Row],[Sales Amount]],0) -> 0.37471742 | AL77: =IF(tblSales[[#This Row],[Discount %]]<=5,"0-5%", IF(tblSales[[#This Row],[Discount %]]<=10,"5-10%", IF(tblSales[[#This Row],[Discount %]]<=15,"10-15%", IF(tblSales[[#This Row],[Discount %]]<=20,"15-20%","20%+")))) -> 0-5%
A78: INV100077 | B78: 45396 | C78: CUST0461 | D78: PRD0228 | E78: STR082 | F78: EMP0127 | G78: 2 | H78: 1419.26 | I78: 20 | J78: 567.7 | K78: 12 | L78: 272.5 | M78: 2543.32 | N78: 1806.6 | O78: =(M78-N78-L78) -> 464.22 | P78: Credit Card | Q78: =TRIM(CLEAN(P78)) -> Credit Card | R78: Online | S78: Not Returned | T78: 15:56 | U78: Weekend | V78: =TEXT(tblSales[[#This Row],[Invoice Date]],"mmm") -> Apr | W78: =MONTH(tblSales[[#This Row],[Invoice Date]]) -> 4 | X78: =YEAR(tblSales[[#This Row],[Invoice Date]]) -> 2024 | Y78: =TEXT(tblSales[[#This Row],[Invoice Date]],"mmm-yyyy") -> Apr-2024 | Z78: =_xlfn.XLOOKUP(tblSales[[#This Row],[Product_ID]],Products!$A:$A,Products!$C:$C,"Women Dresses") -> Wallets | AA78: =_xlfn.XLOOKUP(tblSales[[#This Row],[Product_ID]],Products!$A:$A,Products!$D:$D,"Unknown") -> Bifold Wallet | AB78: =_xlfn.XLOOKUP(tblSales[[#This Row],[Product_ID]],Products!$A:$A,Products!$E:$E,"Unknown") -> Nike | AC78: =_xlfn.XLOOKUP(tblSales[[#This Row],[Store_ID]],Stores!$A:$A,Stores!$B:$B,"Unknown") -> TrendMart Tirupati Standard | AD78: =_xlfn.XLOOKUP(tblSales[[#This Row],[Store_ID]],Stores!$A:$A,Stores!$E:$E,"Unknown") -> South Zone 3 | AE78: =_xlfn.XLOOKUP(tblSales[[#This Row],[Customer_ID]],Customers!$A:$A,Customers!$B:$B,"Unknown") -> Bindu Mishra | AF78: =_xlfn.XLOOKUP(tblSales[[#This Row],[Customer_ID]],Customers!$A:$A,Customers!$J:$J,"Unknown") -> Regular | AG78: =_xlfn.XLOOKUP(tblSales[[#This Row],[Employee_ID]],Employees!$A:$A,Employees!$B:$B,"Unknown") -> Chandra Reddy | AH78: =IF(MONTH(tblSales[[#This Row],[Invoice Date]])>=4,MONTH(tblSales[[#This Row],[Invoice Date]]),MONTH(tblSales[[#This Row],[Invoice Date]])+12) -> 4 | AI78: =DATE(YEAR(tblSales[[#This Row],[Invoice Date]]),MONTH(tblSales[[#This Row],[Invoice Date]]),1) -> 45383 | AJ78: =_xlfn.XLOOKUP(tblSales[[#This Row],[Product_ID]],Products!$A:$A,Products!$B:$B,"Unknown") -> Nike Bifold Wallet Navy Blue | AK78: =IFERROR(tblSales[[#This Row],[Profit]]/tblSales[[#This Row],[Sales Amount]],0) -> 0.1825252 | AL78: =IF(tblSales[[#This Row],[Discount %]]<=5,"0-5%", IF(tblSales[[#This Row],[Discount %]]<=10,"5-10%", IF(tblSales[[#This Row],[Discount %]]<=15,"10-15%", IF(tblSales[[#This Row],[Discount %]]<=20,"15-20%","20%+")))) -> 15-20%
A79: INV100078 | B79: 45443 | C79: CUST0006 | D79: PRD0141 | E79: STR001 | F79: EMP0204 | G79: 4 | H79: 713.19 | I79: 30 | J79: 855.83 | K79: 5 | L79: 99.85 | M79: 2096.78 | N79: 2190.68 | O79: =(M79-N79-L79) -> -193.75 | P79: UPI | Q79: =TRIM(CLEAN(P79)) -> UPI | R79: Offline | S79: Not Returned | T79: 10:22 | U79: Weekday | V79: =TEXT(tblSales[[#This Row],[Invoice Date]],"mmm") -> May | W79: =MONTH(tblSales[[#This Row],[Invoice Date]]) -> 5 | X79: =YEAR(tblSales[[#This Row],[Invoice Date]]) -> 2024 | Y79: =TEXT(tblSales[[#This Row],[Invoice Date]],"mmm-yyyy") -> May-2024 | Z79: =_xlfn.XLOOKUP(tblSales[[#This Row],[Product_ID]],Products!$A:$A,Products!$C:$C,"Women Dresses") -> Women Tops | AA79: =_xlfn.XLOOKUP(tblSales[[#This Row],[Product_ID]],Products!$A:$A,Products!$D:$D,"Unknown") -> Formal Top | AB79: =_xlfn.XLOOKUP(tblSales[[#This Row],[Product_ID]],Products!$A:$A,Products!$E:$E,"Unknown") -> Indian Terrain | AC79: =_xlfn.XLOOKUP(tblSales[[#This Row],[Store_ID]],Stores!$A:$A,Stores!$B:$B,"Unknown") -> TrendMart Kollam Standard | AD79: =_xlfn.XLOOKUP(tblSales[[#This Row],[Store_ID]],Stores!$A:$A,Stores!$E:$E,"Unknown") -> South Zone 1 | AE79: =_xlfn.XLOOKUP(tblSales[[#This Row],[Customer_ID]],Customers!$A:$A,Customers!$B:$B,"Unknown") -> Rajesh Gopalakrishnan | AF79: =_xlfn.XLOOKUP(tblSales[[#This Row],[Customer_ID]],Customers!$A:$A,Customers!$J:$J,"Unknown") -> Gold | AG79: =_xlfn.XLOOKUP(tblSales[[#This Row],[Employee_ID]],Employees!$A:$A,Employees!$B:$B,"Unknown") -> Rahul Krishnan | AH79: =IF(MONTH(tblSales[[#This Row],[Invoice Date]])>=4,MONTH(tblSales[[#This Row],[Invoice Date]]),MONTH(tblSales[[#This Row],[Invoice Date]])+12) -> 5 | AI79: =DATE(YEAR(tblSales[[#This Row],[Invoice Date]]),MONTH(tblSales[[#This Row],[Invoice Date]]),1) -> 45413 | AJ79: =_xlfn.XLOOKUP(tblSales[[#This Row],[Product_ID]],Products!$A:$A,Products!$B:$B,"Unknown") -> Indian Terrain Formal Top Maroon | AK79: =IFERROR(tblSales[[#This Row],[Profit]]/tblSales[[#This Row],[Sales Amount]],0) -> -0.09240359 | AL79: =IF(tblSales[[#This Row],[Discount %]]<=5,"0-5%", IF(tblSales[[#This Row],[Discount %]]<=10,"5-10%", IF(tblSales[[#This Row],[Discount %]]<=15,"10-15%", IF(tblSales[[#This Row],[Discount %]]<=20,"15-20%","20%+")))) -> 20%+
